Workbook

Sheet Wedge Scale
A1: Emission Gap Between BAU and Target Scenario
A3: Total GHG/year (MtCO2e) under 3 different scenarios in 2050
A4: Scenario | B4: Year 2050
A5: CPOS - Current Policy Scenario (BAU) | B5: 2454
A6: TRNS - Transititon Scenario | B6: 1526
A7: LCCP - Low Carbon Scenario Compatible with Paris Agreement Target | B7: 540
A9: Historical net GHG Emission (MtCO2e) for the period 2000 - 2019
A10: Source | B10: 2000 | C10: 2005 | D10: 2010 | E10: 2015 | F10: 2019 | G10: 2025 | H10: 2030 | I10: 2035 | J10: 2040 | K10: 2045 | L10: 2050
A11: Energy | B11: 305.29056 | C11: 377.18269 | D11: 454.9585 | E11: 549.95587 | F11: 655.56789
A12: Industry | B12: 39.80494 | C12: 39.01726 | D12: 31.55031 | E12: 47.84723 | F12: 58.68157
A13: Agriculture | B13: 107.18893 | C13: 110.13156 | D13: 108.08176 | E13: 128.04526 | F13: 126.65716
A14: Waste | B14: 59.22757 | C14: 71.10281 | D14: 88.65723 | E14: 99.69468 | F14: 128.10725
A15: LULUCF | B15: 342.99131 | C15: 709.68107 | D15: 529.52217 | E15: 1730.2759 | F15: 818.65399
A16: Total | B16: =SUM(B11:B15) -> 854.50331 | C16: =SUM(C11:C15) -> 1307.1154 | D16: =SUM(D11:D15) -> 1212.77 | E16: =SUM(E11:E15) -> 2555.8189 | F16: =SUM(F11:F15) -> 1787.6679
A17: CPOS | L17: 2454
A18: LCCP | L18: 540
A20: Rescaling Global Stabilisation Wedge
A22: Population Principle
A23: Using average of 2020 and 2050 population
A25: Indonesia Population 2020 & 2050 (Projection)
A26: 2020 | B26: 2050 | E26: Average
B27: Trend Scenario | C27: Optimist Scenario | D27: Moderate Scenario
A28: 269580000 | B28: 328930000 | C28: 337990000 | D28: 333570000 | E28: =AVERAGE(A28:B28) -> 299255000
A29: World Population 2020 & 2050 (Projection)
A30: 2020 | B30: 2050 | E30: Average
B31: Upper Limit | C31: Lower Limit | D31: Median
A32: 7887000764 | B32: 10200000000 | C32: 9400000000 | D32: =(B32+C32)/2 -> 9800000000 | E32: =AVERAGE(A32,D32) -> 8843500382
A34: GDP Principle (Sensitivity Analysis)
A35: Using GDP 2050 Projection (MER)
A36: Indonesia 2050 GDP (at constant 2016 US$bn) | B36: World 2050 GDP (at constant 2016 US$bn) | C36: Indonesia's GDP Share
A37: 7275 | B37: =49583+34102+28021+7275+6779+6532+6138+5563+5369+5127+4705+4087+3539+3495+3282+3115+3100+2990+2831+2732+2586+2564+2536+2280+2263+2103+2103+2054+1995+1939+1591+1496 -> 213875 | C37: =A37/B37 -> 0.034015196
A39: Scale | B39: Timeframe (year) | C39: Wedge Size
C40: Annual (GtCO2e) | D40: Annual (MtCO2e) | E40: Cumulative (MtCO2e)
A41: Global | B41: 30 | C41: 2 | D41: =C41*1000 -> 2000 | E41: =D41*B41/2 -> 30000
A42: Indonesia - Population | B42: 30 | C42: =C41*(E28/E32) -> 0.067677953 | D42: =C42*1000 -> 67.677953 | E42: =D42*B42/2 -> 1015.1693
A43: Indonesia - GDP | B43: 30 | C43: =C41*C37 -> 0.068030392 | D43: =C43*1000 -> 68.030392 | E43: =D43*B43/2 -> 1020.4559
A45: Amount of Required Wedges in Indonesia's Context
A46: Population Principle
A47: Calculation with Annual Gap
A48: Annual Emission Gap (MtCO2e) | B48: Annual Wedge - Population (MtCO2e) | C48: N Wedges Required - Population
...

Sheet Effort & Upper Bound
B2: EFFORT & UPPER BOUND ESTIMATES
B3: Wedge Size (MtCO2e/year) | D3: 67.677953
B5: ELECTRICITY
B6: Strategy ID | C6: Strategy Name | D6: Unit | E6: Wedge Target | F6: Wedge Share | G6: Meaning of Wedge Share | H6: Addressable Market | I6: Unit | J6: Wedge Scale Upper Bound
B7: E1 | C7: Build more solar farms | D7: TWh (Output) | E7: =$D$3/('Power Sector Inputs'!$D$65/1000) -> 63.078254 | F7: =E7/'Power Sector Inputs'!$D$56 -> 0.030721774 | G7: Build more solar farms to generate 3% of national electricity | H7: =SUM('Power Sector Inputs'!$D$44,'Power Sector Inputs'!$D$46,'Power Sector Inputs'!$D$48) -> 1229.92 | I7: TWh (Output) | J7: =H7/E7 -> 19.49832
B8: E2 | C8: Build more wind farms | D8: TWh (Output) | E8: =$D$3/('Power Sector Inputs'!$D$65/1000) -> 63.078254 | F8: =E8/'Power Sector Inputs'!$D$56 -> 0.030721774 | G8: Build more wind farms to generate 3% of national electricity | H8: =SUM('Power Sector Inputs'!$D$44,'Power Sector Inputs'!$D$46,'Power Sector Inputs'!$D$48) -> 1229.92 | I8: TWh (Output) | J8: =H8/E8 -> 19.49832
B9: E3 | C9: Build more nuclear reactors | D9: TWh (Output) | E9: =$D$3/('Power Sector Inputs'!$D$65/1000) -> 63.078254 | F9: =E9/'Power Sector Inputs'!$D$56 -> 0.030721774 | G9: Build more nuclear reactors to generate 3% of national electricity | H9: =SUM('Power Sector Inputs'!$D$44,'Power Sector Inputs'!$D$46,'Power Sector Inputs'!$D$48) -> 1229.92 | I9: TWh (Output) | J9: =H9/E9 -> 19.49832
B10: E4 | C10: Build more hydro power plants | D10: TWh (Output) | E10: =$D$3/('Power Sector Inputs'!$D$65/1000) -> 63.078254 | F10: =E10/'Power Sector Inputs'!$D$56 -> 0.030721774 | G10: Build more hydro power plants to generate 3% of national electricity | H10: 289.7 | I10: TWh (Output) | J10: =H10/E10 -> 4.5927079
B11: E5 | C11: Switch coal to gas plants | D11: TWh (Output) | E11: =$D$3/(('Power Sector Inputs'!D60/1000)-('Power Sector Inputs'!D62/1000)) -> 105.66538 | F11: =E11/'Power Sector Inputs'!$D$56 -> 0.051463503 | G11: Switch from coal to gas plants for 5% of national electricity | H11: ='Power Sector Inputs'!D44 -> 1001.51 | I11: TWh (Output) | J11: =H11/E11 -> 9.4781282
B12: E6 | C12: Retrofit coal plants with CCS | D12: TWh (Output) | E12: =$D$3/(('Power Sector Inputs'!E60/1000)-('Power Sector Inputs'!E61/1000)) -> 76.095717 | F12: =E12/'Power Sector Inputs'!$D$56 -> 0.037061829 | G12: Retrofit coal plants with CCS for 4% of national electricity | H12: ='Power Sector Inputs'!D44 -> 1001.51 | I12: TWh (Output) | J12: =H12/E12 -> 13.161188
B13: E7 | C13: Power BECCS using waste | D13: TWh (Output) | E13: =$D$3/(('Power Sector Inputs'!D65/1000)-('Power Sector Inputs'!I79)) -> 42.591588 | F13: =E13/'Power Sector Inputs'!$D$56 -> 0.020743902 | G13: Power BECCS using waste for 2% of national electricity | H13: 399.47222 | I13: TWh (Output) | J13: =H13/E13 -> 9.3791343
B14: E8 | C14: Retrofit gas plants with CCS | D14: TWh (Output) | E14: =$D$3/(('Power Sector Inputs'!E62/1000)-('Power Sector Inputs'!E63/1000)) -> 190.07084 | F14: =E14/'Power Sector Inputs'!$D$56 -> 0.09257253 | G14: Retrofit gas plants with CCS for 9% of national electricity | H14: ='Power Sector Inputs'!D46 -> 205.82 | I14: TWh (Output) | J14: =H14/E14 -> 1.0828594
B16: LAND USE & FOOD
B17: Strategy ID | C17: Strategy Name | D17: Unit | E17: Wedge Target | F17: Wedge Share | G17: Meaning of Wedge Share | H17: Addressable Market | I17: Unit | J17: Wedge Scale Upper Bound
B18: L1 | C18: Reduce Tropical Forest Loss | D18: Mha/year | E18: =$D$3/'Land Use & Food Inputs'!E16 -> 0.29040997 | F18: =-(E18/'Land Use & Food Inputs'!B16) -> -0.59673281 | G18: Reduce tropical forest loss by 60% of the projected loss rate | H18: ='Land Use & Food Inputs'!B16 -> 0.48666667 | I18: Mha/year | J18: =H18/E18 -> 1.6757919
B19: L2 | C19: Rewet Tropical Peatlands | D19: Mha | E19: =($D$3)/('Land Use & Food Inputs'!C24-'Land Use & Food Inputs'!D24) -> 7.184496 | F19: =E19/'Land Use & Food Inputs'!B24 -> 0.60166972 | G19: Rewet tropical peatland in 60% of current area | H19: ='Land Use & Food Inputs'!B24 -> 11.94093 | I19: Mha | J19: =H19/E19 -> 1.6620414
B20: L3 | C20: Phase-out Peatland Drainage | D20: Mha/year | E20: =($D$3)/('Land Use & Food Inputs'!C24*30) -> 0.051979994 | F20: =-(E20/'Land Use & Food Inputs'!E24) -> -0.22119147 | G20: Reduce peatland drainage by 22% relative to its current rate | H20: ='Land Use & Food Inputs'!E24 -> 0.235 | I20: Mha/year | J20: =H20/E20 -> 4.5209701
B21: L4 | C21: Reforest the Tropics | D21: Mha | E21: =D3/(('Land Use & Food Inputs'!F20+'Land Use & Food Inputs'!G20)*0.5) -> 3.1850397 | F21: =E21/'Land Use & Food Inputs'!D8 -> 0.05030069 | G21: Expanding forest area in 2050 by 5% | H21: =30107242/1000000 -> 30.107242 | I21: Mha | J21: =H21/E21 -> 9.4527055
B22: L5 | C22: Add Trees to Tropical Pasture | D22: Mha | E22: =$D$3/'Land Use & Food Inputs'!F29 -> 4.3946722 | F22: =E22/'Land Use & Food Inputs'!D7 -> 0.1472252 | G22: Add trees to tropical pasture across 15% of pasture area in 2050 | H22: ='Land Use & Food Inputs'!D7 -> 29.85 | I22: Mha | J22: =H22/E22 -> 6.7923154
B23: L6 | C23: Add Trees to Tropical Cropland | D23: Mha | E23: =$D$3/'Land Use & Food Inputs'!F28 -> 5.1271176 | F23: =E23/'Land Use & Food Inputs'!D6 -> 0.12078195 | G23: Add trees to tropical cropland across 12% of cropland area in 2050 | H23: ='Land Use & Food Inputs'!D6 -> 42.449371 | I23: Mha | J23: =H23/E23 -> 8.2793831
B24: L7 | C24: Apply Soil Carbon Management | D24: Mha | E24: ='Calc. Soil Carbon'!H38 -> 58.362438 | F24: =E24/'Land Use & Food Inputs'!D6 -> 1.3748717 | G24: The strategy could only achieve 70% of a full wedge | H24: ='Land Use & Food Inputs'!D6 -> 42.449371 | I24: Mha | J24: =H24/E24 -> 0.72734061
B25: L8 | C25: Apply enhanced weathering in croplands | D25: Mha | E25: ='Land Use & Food Inputs'!C12/'Land Use & Food Inputs'!B12*1000 -> 9.5 | F25: =E25/'Land Use & Food Inputs'!D6 -> 0.22379601 | G25: Apply enhanced weathering to 23% of national cropland | H25: ='Land Use & Food Inputs'!D6 -> 42.449371 | I25: Mha | J25: =H25/E25 -> 4.4683548
B26: L9 | C26: Reduce Meat Consumption | D26: Kcal/Capita/Day | E26: =D3/'Land Use & Food Inputs'!K38*SUM('Land Use & Food Inputs'!B38:D38) -> 65.459415 | F26: =-(E26/SUM('Land Use & Food Inputs'!B38:D38)) -> -0.59294023 | G26: Eat less meat by 59% relative to meat consumption projection in 2050 | H26: =SUM('Land Use & Food Inputs'!B38:D38) -> 110.398 | I26: Kcal/Capita/Day | J26: =H26/E26 -> 1.6865106
B27: L10 | C27: Reduce Food Loss and Waste | D27: Mt | E27: =F27*'Land Use & Food Inputs'!C42 -> -28.413211 | F27: =-(D3/'Land Use & Food Inputs'!E42) -> -0.69447817 | G27: Reduce food loss and waste by 69% nationally | H27: ='Land Use & Food Inputs'!C42 -> 40.913037 | I27: Mt | J27: =-(H27/E27) -> 1.4399301
B29: TRANSPORT
B30: Strategy ID | C30: Strategy Name | D30: Unit | E30: Wedge Target | F30: Wedge Share | G30: Meaning of Wedge Share | H30: Addressable Market | I30: Unit | J30: Wedge Scale Upper Bound
B31: T1 | C31: Avoid Car travel or Walk/Cycle | D31: Trillion p-km | E31: =D3/'Transport Inputs'!D40 -> 0.62003849 | F31: =-E31/'Transport Inputs'!I55 -> -0.12970198 | G31: Avoid car travel, walk or cycle for 13% of national pax travel in 2050 | H31: ='Transport Inputs'!I46 -> 0.91693635 | I31: Trillion p-km | J31: =H31/E31 -> 1.4788378
B32: T2 | C32: Deploy More Electric Vehicles | D32: Trillion p-km | E32: =(D3)/('Transport Inputs'!D40-'Transport Inputs'!D41) -> 0.62613955 | F32: =E32/'Transport Inputs'!I55 -> 0.13097822 | G32: Deploy more electric vehicle for 13% of national pax travel in 2050 | H32: ='Transport Inputs'!I46 -> 0.91693635 | I32: Trillion p-km | J32: =H32/E32 -> 1.4644281
B33: T3 | C33: Deploy More Biofuels | D33: Trillion p-km | E33: =(D3/(('Power Sector Inputs'!H9-'Transport Inputs'!F64)*('Transport Inputs'!D9*3.6)))*'Transport Inputs'!D32 -> -2.0182771 | F33: =E33/'Transport Inputs'!I55 -> -0.42219079 | G33: - | H33: - | I33: - | J33: -
B34: T4 | C34: Use More Public Transport | D34: Trillion p-km | E34: =D3/('Transport Inputs'!D40-'Transport Inputs'!D39) -> 0.85234227 | F34: =E34/'Transport Inputs'!I55 -> 0.17829616 | G34: Use more public transport for 18% of national pax travel in 2050 | H34: ='Transport Inputs'!I46 -> 0.91693635 | I34: Trillion p-km | J34: =H34/E34 -> 1.0757842
B35: T5 | C35: Decarbonise Freight Road | D35: MtCO2e | E35: =D3 -> 67.677953 | F35: =-E35/'Transport Inputs'!H77 -> -0.51262322 | G35: Decarbonise freight road by 51% nationally | H35: ='Transport Inputs'!H77 -> 132.0228 | I35: MtCO2e | J35: =H35/E35 -> 1.9507505
B36: T6 | C36: Avoid Taking Flights | D36: Trillion p-km | E36: =(D3/(((SUM('Power Sector Inputs'!C9:E9)*3.6*1.7)+('Power Sector Inputs'!F9*3.6))*'Transport Inputs'!D70))*'Transport Inputs'!D69 -> 0.43999372 | F36: =-E36/('Transport Inputs'!D68/1000) -> -0.98748576 | G36: Fly less reducing national pax travel by 99% | H36: ='Transport Inputs'!D68/1000 -> 0.44556969 | I36: Trillion p-km | J36: =H36/E36 -> 1.0126728
B37: T7 | C37: Improve Efficiency of Cars | D37: l/100km | E37: =('Transport Inputs'!D9-((D3*1000)/('Transport Inputs'!D8*'Power Sector Inputs'!H9*3.6)))/8.94*100 -> 3.4913033 | F37: =((E37*8.94/100)-'Transport Inputs'!C9)/'Transport Inputs'!C9 -> -0.55806288 | G37: Improve the efficiency of cars by reducing current fuel use by 56% | H37: =E37 -> 3.4913033 | I37: l/100km | J37: =H37/E37 -> 1
B39: BUILDING
B40: Strategy ID | C40: Strategy Name | D40: Unit | E40: Wedge Target | F40: Wedge Share | G40: Meaning of Wedge Share | H40: Addressable Market | I40: Unit | J40: Wedge Scale Upper Bound
B41: B1 | C41: Reduce Building Heat Transfer | D41: W/m2*K | E41: ='Buildings Inputs'!D15*(1-('Effort & Upper Bound'!D3/'Buildings Inputs'!D19)) -> 0.68831953 | F41: =(E41/'Buildings Inputs'!C15)-1 -> -0.63772656 | G41: Reduce building heat transfer by 64% compared to current stock | H41: =E41 -> 0.68831953 | I41: W/m2*K | J41: =H41/E41 -> 1
B42: B2 | C42: Deploy More Clean Stoves | D42: Million | E42: =(D3)/('Buildings Inputs'!H6-'Buildings Inputs'!I6) -> 44.217386 | F42: =E42/('Buildings Inputs'!J6/1000000*'Buildings Inputs'!K6) -> 5.3235702 | G42: The strategy could only achieve 20% of a full wedge | H42: ='Buildings Inputs'!J6*'Buildings Inputs'!K6/1000000 -> 8.3059648 | I42: Million | J42: =H42/E42 -> 0.18784386
B44: INDUSTRY
B45: Strategy ID | C45: Strategy Name | D45: Unit | E45: Wedge Target | F45: Wedge Share | G45: Meaning of Wedge Share | H45: Addressable Market | J45: Wedge Scale Upper Bound
B46: I1 | C46: Produce Clean Hydrogen | D46: Mt | E46: =(((D3*10^12)/('Industry Inputs'!D24-'Industry Inputs'!E24))/33000)/1000000 -> 3.3160043 | F46: =E46/'Industry Inputs'!E25 -> 0.58054486 | G46: Produce clean hydrogen by 58% of 2050 demand | H46: ='Industry Inputs'!E25 -> 5.711883 | I46: Mt | J46: =H46/E46 -> 1.7225198
...

Sheet Power Sector Inputs
B2: DATA INVENTORY - POWER/ELECTRICITY
B4: TABLE 1 - Emission Factors for Fossil Fuels (gCO₂e MJ⁻¹, LHV)
B5: Fuel | C5: Combustion | F5: Indirect | G5: Indirect (% overhead) | H5: Combined
C6: CO2 | D6: CH4 | E6: N2O
B7: Coal | C7: =106476/1000 -> 106.476 | D7: =1*28/1000 -> 0.028 | E7: =1.5*265/1000 -> 0.3975 | F7: =C7*G7 -> 7.9857 | G7: 0.075 | H7: =C7+D7+E7+F7 -> 114.8872
B8: Gas | C8: =57.64 -> 57.64 | D8: =3*28/1000 -> 0.084 | E8: =0.1*265/1000 -> 0.0265 | F8: =C8*G8 -> 14.41 | G8: 25% | H8: =C8+D8+E8+F8 -> 72.1605
B9: Oil | C9: =73300/1000 -> 73.3 | D9: =3*28/1000 -> 0.084 | E9: =0.6*265/1000 -> 0.159 | F9: =C9*G9 -> 14.66 | G9: 20% | H9: =C9+D9+E9+F9 -> 88.203
B11: TABLE S10 — Net Power Plant Efficiencies (%, LHV)
B12: Source: Global Calculator (ref.69). HHV→LHV conversion applied (ratios: coal 1.050, oil 1.052, gas 1.109). Net efficiency = gross efficiency minus plant self-consumption. Indonesia action: obtain average efficiency of existing fleet from PLN Statistik Ketenagalistrikan.
B13: Plant Type | C13: Gross HHV (2011, %) | D13: Net HHV (2011, %) | E13: Gross LHV (2011, %) | F13: Net LHV (2011, %) | G13: Indonesia Net LHV (%) | H13: Indonesia Source | I13: Status
B14: Ultracritical coal | C14: 41.4 | D14: 38.7 | E14: 43.5 | F14: 40.6 | H14: PLN Statistik Ketenagalistrikan | I14: ❌ Not Found
B15: Supercritical coal | C15: 37.6 | D15: 35.1 | E15: 39.4 | F15: 36.8 | H15: PLN Statistik Ketenagalistrikan | I15: ❌ Not Found
B16: Subcritical coal | C16: 34.7 | D16: 32.4 | E16: 36.5 | F16: 34 | H16: PLN Statistik Ketenagalistrikan | I16: ❌ Not Found
B17: Average coal | C17: 35.6 | D17: 33.3 | E17: 37.4 | F17: 34.9 | H17: PLN Statistik Ketenagalistrikan | I17: ❌ Not Found
B18: New oil | C18: 40 | D18: 37.3 | E18: 42.1 | F18: 39.3 | H18: PLN Statistik Ketenagalistrikan | I18: ❌ Not Found
B19: Old oil | C19: 32 | D19: 29.9 | E19: 33.7 | F19: 31.4 | H19: PLN Statistik Ketenagalistrikan | I19: ❌ Not Found
B20: Average oil | C20: 34 | D20: 31.8 | E20: 35.8 | F20: 33.4 | H20: PLN Statistik Ketenagalistrikan | I20: ❌ Not Found
B21: OCGT (gas open cycle) | C21: 38.2 | D21: 35.6 | E21: 42.3 | F21: 39.5 | H21: PLN Statistik Ketenagalistrikan | I21: ❌ Not Found
B22: CCGT (gas combined) | C22: 48.8 | D22: 45.6 | E22: 54.1 | F22: 50.5 | H22: PLN Statistik Ketenagalistrikan | I22: ❌ Not Found
B23: Average gas | C23: 44.5 | D23: 41.5 | E23: 49.3 | F23: 46 | H23: PLN Statistik Ketenagalistrikan | I23: ❌ Not Found
B24: TABLE 2 - Net Efficiency of Generators for Base Year and 2050 Projection (%, LHV)
B25: These are the 2050 projected efficiencies used in wedge calculations. Indonesia action: cross-check with RUPTL 2021–2030 assumptions for new-build plant efficiency. If Indonesia builds new coal or gas plants to 2050 (CPOS scenario), use Indonesian RUPTL efficiency; otherwise use global averages as proxy.
B26: Type of Generator | C26: Base Year 2020 | D26: Projection for 2050 - ERIA
B27: Coal (Unabated) | C27: 0.26 | D27: 0.35
B28: CCS Coal | C28: - | D28: =D27-0.12 -> 0.23
B29: Gas (Unabated) | C29: 0.39 | D29: 0.48
B30: CCS Gas | C30: - | D30: =D29-0.0875 -> 0.3925
B31: Oil | C31: 0.29 | D31: 0.29
B33: TABLE 3 - Fuel Input to Power Plants by Generator Type (TWh)
B34: Generator Type | C34: Base Year 2020 | D34: Projection for 2050 - BAU | E34: Projection for 2050 - Low Carbon
B35: Coal (Unabated) | C35: =C44/C27 -> 695.69231 | D35: =D44/D27 -> 2861.4571 | E35: =E44/D27 -> 500.45714
B36: CCS Coal | C36: - | D36: - | E36: =E45/D28 -> 2515.4783
B37: Gas (Unabated) | C37: =C46/C29 -> 131.47692 | D37: =D46/D29 -> 428.79167 | E37: =E46/D29 -> 97.653892
B38: CCS Gas | C38: - | D38: - | E38: =E47*D30 -> 60.769257
B39: Oil | C39: =C48/C31 -> 23.324138 | D39: =D48/D31 -> 77.896552 | E39: =E48/D31 -> 64.034483
B40: TOTAL | C40: =SUM(C35:C39) -> 850.49337 | D40: =SUM(D35:D39) -> 3368.1454 | E40: =SUM(E35:E39) -> 3238.393
B42: TABLE 4 - Electricity Supplied to Grid by Generator Type (TWh)
B43: Generator Type | C43: Base Year 2020 | D43: Projection for 2050 - BAU | E43: Projection for 2050 - Low Carbon
B44: Coal (Unabated) | C44: 180.88 | D44: 1001.51 | E44: 175.16
B45: CCS Coal | C45: - | D45: - | E45: 578.56
...

Sheet Land Use & Food Inputs
B2: DATA INVENTORY — LAND USE & FOOD
B4: TABLE 17 - Indonesia Land Usage in Million Hectares (Mha) 2020 & 2050 | H4: Data from different sources | I4: ha | J4: Mha
B5: Land Use | C5: 2020 | D5: 2050 | H5: Cropland 2020 FAO | I5: 43382320 | J5: =I5/1000000 -> 43.38232
B6: Cropland | C6: 43.38232 | D6: 42.449371 | H6: Cropland 2020 FABLE | I6: 83532930 | J6: =I6/1000000 -> 83.53293
B7: Pasture | C7: 13.47 | D7: 29.85 | H7: Correction Factor (FAO - FABLE) | I7: =J5/J6 -> 0.51934393 | J7: 0.51934393
B8: Forest | C8: 85.32 | D8: 63.32 | H8: Cropland 2050 FABLE | I8: 81736530 | J8: =I8/1000000 -> 81.73653
H9: Cropland 2050 FABLE (correction) | I9: =I8*I7 -> 42449371 | J9: =I9/1000000 -> 42.449371
B10: TABLE 9 - Inputs for Enhanced Weathering in Croplands Strategy
B11: Application Rate of Basalt (t/ha/year) | C11: Silicate Demand (Gt/year)
B12: 40 | C12: 0.38
B14: TABLE 10 - Inputs for Reduce Tropical Forest Loss Strategy
B15: Tropical Forest Loss Rate (Mha/year) | C15: Total annual deforestation area 2006–2020 (ha/year) | D15: Net emissions from deforestation (tCO₂e/year) | E15: Net Emission Factor for Deforestation (tCO₂e/ha)
B16: =14.6/30 -> 0.48666667 | C16: 599232 | D16: 139646704 | E16: =D16/C16 -> 233.0428
B18: TABLE 11 - Inputs for Reforest the Tropics Strategy
B19: Above-Ground Biomass Growth (Natural) (tonnes d.m/ha.year) | C19: Above-Ground Biomass Growth (Plantation) (tonnes d.m/ha.year) | D19: Ratio of Below-Ground Biomass to Above-Ground Biomass | E19: Carbon Fraction of Forest Biomass (tC/tonnes.d.m) | F19: Rates of Carbon Accumulation in Forest (Natural) (tCO₂/ha/year) | G19: Rates of Carbon Accumulation in Forest (Plantation) (tCO₂/ha/year)
B20: 13 | C20: 5 | D20: 0.37 | E20: 0.47 | F20: =B20*(1+$D$20)*$E$20*(44/12) -> 30.692567 | G20: =C20*(1+$D$20)*$E$20*(44/12) -> 11.804833
B22: TABLE 12 - Inputs for Rewet Peatlands and Stop Drainage Strategy
B23: Area of Drained Peatland (Mha) | C23: Emission Factor - Drained (tCO₂/ha.year) | D23: Emission Factor - Rewetted (tCO₂/ha.year) | E23: Rate of Peatland Drainage (Mha/year)
B24: =20949000/1000000*0.57 -> 11.94093 | C24: 43.4 | D24: 33.98 | E24: 0.235
B26: TABLE 13 - Inputs for Add Trees to Tropical Pasture and Cropland Strategy
B27: Practice | C27: Above-Ground Sequestration Rate (tCO₂/ha.year) | D27: Below-Ground Sequestration Rate (tCO₂/ha.year) | E27: Soil Sequestration Rate (tCO₂/ha.year) | F27: Total (tCO₂/ha.year)
B28: Tropical Alley Cropping | C28: 8.7 | D28: 2 | E28: 2.5 | F28: =SUM(C28:E28) -> 13.2
B29: Tropical Silvopasture | C29: 10.7 | D29: 2.9 | E29: 1.8 | F29: =SUM(C29:E29) -> 15.4
B31: TABLE 14 - Inputs for Apply Soil Carbon Management Strategy
B32: Initial Soil Organic Carbon Content (SOC-0) (%) | C32: a | D32: b | E32: T-0 (year) | F32: Bulk Density (g/cm3)
B33: 71 | C33: 0.697 | D33: 11.5 | E33: 4 | F33: 1.038
B35: TABLE 15 - Inputs for Reduce Meat Consumption Strategy
B36: 2050 Meat Consumption (Kcal/cap/day) | E36: 2050 Meat Consumption (Kcal/day) | H36: Emission Factor (gCO₂e/kcal) | K36: Emission (MtCO₂e/year)
B37: Ruminant Meats | C37: Pork | D37: Poultry | E37: Ruminant Meats | F37: Pork | G37: Poultry | H37: Ruminant Meats | I37: Pork | J37: Poultry
B38: 23.692 | C38: 46.289 | D38: 40.417 | E38: =B38*'Wedge Scale'!$B$28 -> 7793009560 | F38: =C38*'Wedge Scale'!$B$28 -> 15225840770 | G38: =D38*'Wedge Scale'!$B$28 -> 13294363810 | H38: 20.533333 | I38: 5.8666667 | J38: 4.7666667 | K38: =((E38*H38)+(F38*I38)+(G38*J38))*365/(10^12) -> 114.13959
B40: TABLE 16 - Inputs for Reduce Food Loss and Waste Strategy
B41: Total Food Loss and Waste 2020 (Mt) | C41: Total Food Loss and Waste 2050 (Mt) | D41: Emission from FLW 2020 (MtCO₂e) | E41: Emission from FLW 2050 (MtCO₂e)
B42: ='Food loss and waste (IDN)'!P53 -> 37.939785 | C42: ='Food loss and waste (IDN)'!P54 -> 40.913037 | D42: ='Emissions (IDN)'!P54 -> 75.41555 | E42: ='Emissions (IDN)'!P55 -> 97.451519

Sheet Calc. Soil Carbon
A1: Soil carbon sequestration
A2: Input parameters for sigmoid function
B4: SOC-0 | C4: a | D4: b | E4: t-0 | F4: bulk density (g/cm3)
B5: 0.71 | C5: 0.697 | D5: 11.5 | E5: 4 | F5: ='Land Use & Food Inputs'!F33 -> 1.038
A7: Year | B7: %-SOC (med) | C7: Mg C ha yr (med) | E7: Year | F7: Wedge target (tC/yr) | G7: Linear emissions savings (annual area) (ha yr) | H7: Linear emissions savings (cumulative area) (Mha)
A8: 1 | B8: =$B$5 + ($C$5 / (1 + EXP(-(A8-$E$5) /$D$5))) -> 1.0132995 | C8: =0.519*(1.038/1.3) -> 0.41440154 | E8: 2020 | F8: 0 | H8: 0
A9: 2 | B9: =$B$5 + ($C$5 / (1 + EXP(-(A9-$E$5) /$D$5))) -> 1.0282718 | C9: =(B9-B8)*$F$5*30 -> 0.4662368 | E9: 2021 | F9: =(68/30)*$A8*1000000/3.67 -> 617620.35 | G9: =$F9/C9 -> 1324692.4 | H9: =SUM(G$8:G9)/1000000 -> 1.3246924
A10: 3 | B10: =$B$5 + ($C$5 / (1 + EXP(-(A10-$E$5) /$D$5))) -> 1.0433574 | C10: =(B10-B9)*$F$5*30 -> 0.46976444 | E10: 2022 | F10: =(68/30)*$A9*1000000/3.67 -> 1235240.7 | G10: =(($F10-SUMPRODUCT(G$9:G9, C$10:C10))/C$9) -> 1314669.5 | H10: =SUM(G$8:G10)/1000000 -> 2.6393619
A11: 4 | B11: =$B$5 + ($C$5 / (1 + EXP(-(A11-$E$5) /$D$5))) -> 1.0585 | C11: =(B11-B10)*$F$5*30 -> 0.47154161 | E11: 2023 | F11: =(68/30)*$A10*1000000/3.67 -> 1852861 | G11: =(($F11-SUMPRODUCT(G$9:G10, C$10:C11))/C$9) -> 1309734.2 | H11: =SUM(G$8:G11)/1000000 -> 3.9490961
A12: 5 | B12: =$B$5 + ($C$5 / (1 + EXP(-(A12-$E$5) /$D$5))) -> 1.0736426 | C12: =(B12-B11)*$F$5*30 -> 0.47154161 | E12: 2024 | F12: =(68/30)*$A11*1000000/3.67 -> 2470481.4 | G12: =(($F12-SUMPRODUCT(G$9:G11, C$10:C12))/C$9) -> 1309790.3 | H12: =SUM(G$8:G12)/1000000 -> 5.2588865
A13: 6 | B13: =$B$5 + ($C$5 / (1 + EXP(-(A13-$E$5) /$D$5))) -> 1.0887282 | C13: =(B13-B12)*$F$5*30 -> 0.46976444 | E13: 2025 | F13: =(68/30)*$A12*1000000/3.67 -> 3088101.7 | G13: =(($F13-SUMPRODUCT(G$9:G12, C$10:C13))/C$9) -> 1314782.3 | H13: =SUM(G$8:G13)/1000000 -> 6.5736687
A14: 7 | B14: =$B$5 + ($C$5 / (1 + EXP(-(A14-$E$5) /$D$5))) -> 1.1037005 | C14: =(B14-B13)*$F$5*30 -> 0.4662368 | E14: 2026 | F14: =(68/30)*$A13*1000000/3.67 -> 3705722.1 | G14: =(($F14-SUMPRODUCT(G$9:G13, C$10:C14))/C$9) -> 1324692.4 | H14: =SUM(G$8:G14)/1000000 -> 7.8983611
A15: 8 | B15: =$B$5 + ($C$5 / (1 + EXP(-(A15-$E$5) /$D$5))) -> 1.1185049 | C15: =(B15-B14)*$F$5*30 -> 0.46101121 | E15: 2027 | F15: =(68/30)*$A14*1000000/3.67 -> 4323342.4 | G15: =(($F15-SUMPRODUCT(G$9:G14, C$10:C15))/C$9) -> 1339539.6 | H15: =SUM(G$8:G15)/1000000 -> 9.2379007
A16: 9 | B16: =$B$5 + ($C$5 / (1 + EXP(-(A16-$E$5) /$D$5))) -> 1.1330895 | C16: =(B16-B15)*$F$5*30 -> 0.45416442 | E16: 2028 | F16: =(68/30)*$A15*1000000/3.67 -> 4940962.8 | G16: =(($F16-SUMPRODUCT(G$9:G15, C$10:C16))/C$9) -> 1359377.4 | H16: =SUM(G$8:G16)/1000000 -> 10.597278
A17: 10 | B17: =$B$5 + ($C$5 / (1 + EXP(-(A17-$E$5) /$D$5))) -> 1.1474054 | C17: =(B17-B16)*$F$5*30 -> 0.44579497 | E17: 2029 | F17: =(68/30)*$A16*1000000/3.67 -> 5558583.1 | G17: =(($F17-SUMPRODUCT(G$9:G16, C$10:C17))/C$9) -> 1384293.4 | H17: =SUM(G$8:G17)/1000000 -> 11.981571
A18: 11 | B18: =$B$5 + ($C$5 / (1 + EXP(-(A18-$E$5) /$D$5))) -> 1.1614073 | C18: =(B18-B17)*$F$5*30 -> 0.43602032 | E18: 2030 | F18: =(68/30)*$A17*1000000/3.67 -> 6176203.5 | G18: =(($F18-SUMPRODUCT(G$9:G17, C$10:C18))/C$9) -> 1414407.5 | H18: =SUM(G$8:G18)/1000000 -> 13.395979
A19: 12 | B19: =$B$5 + ($C$5 / (1 + EXP(-(A19-$E$5) /$D$5))) -> 1.1750545 | C19: =(B19-B18)*$F$5*30 -> 0.42497337 | E19: 2031 | F19: =(68/30)*$A18*1000000/3.67 -> 6793823.8 | G19: =(($F19-SUMPRODUCT(G$9:G18, C$10:C19))/C$9) -> 1449871.9 | H19: =SUM(G$8:G19)/1000000 -> 14.845851
A20: 13 | B20: =$B$5 + ($C$5 / (1 + EXP(-(A20-$E$5) /$D$5))) -> 1.1883107 | C20: =(B20-B19)*$F$5*30 -> 0.41279888 | E20: 2032 | F20: =(68/30)*$A19*1000000/3.67 -> 7411444.1 | G20: =(($F20-SUMPRODUCT(G$9:G19, C$10:C20))/C$9) -> 1490870.1 | H20: =SUM(G$8:G20)/1000000 -> 16.336721
A21: 14 | B21: =$B$5 + ($C$5 / (1 + EXP(-(A21-$E$5) /$D$5))) -> 1.2011447 | C21: =(B21-B20)*$F$5*30 -> 0.39964959 | E21: 2033 | F21: =(68/30)*$A20*1000000/3.67 -> 8029064.5 | G21: =(($F21-SUMPRODUCT(G$9:G20, C$10:C21))/C$9) -> 1537616.1 | H21: =SUM(G$8:G21)/1000000 -> 17.874337
... A37: 30 | B37: =$B$5 + ($C$5 / (1 + EXP(-(A37-$E$5) /$D$5))) -> 1.3411921 | C37: =(B37-B36)*$F$5*30 -> 0.16716206 | E37: 2049 | F37: =(68/30)*$A36*1000000/3.67 -> 17910990 | G37: =(($F37-SUMPRODUCT(G$9:G36, C$10:C37))/C$9) -> 3353368.7 | H37: =SUM(G$8:G37)/1000000 -> 54.804809
A38: 31 | B38: =$B$5 + ($C$5 / (1 + EXP(-(A38-$E$5) /$D$5))) -> 1.3461946 | C38: =(B38-B37)*$F$5*30 -> 0.15577967 | E38: 2050 | F38: =(68/30)*$A37*1000000/3.67 -> 18528610 | G38: =(($F38-SUMPRODUCT(G$9:G37, C$10:C38))/C$9) -> 3557629.1 | H38: =SUM(G$8:G38)/1000000 -> 58.362438 | I38: Effort required for a wedge

Sheet Calc. Meat Cons.
F1: Back to index
A3: Country | B3: Cluster | C3: 2050Population | D3: FAOFoodItem | E3: KcalPerCap | F3: TotalKCal2050 | G3: T&C category | H3: PerKcalEmissions | I3: TotalEmissions2050 | J3: EmissionsPerCap
A4: Afghanistan | B4: =_xlfn.XLOOKUP(A4,'[1]2050Pop'!$A$7:$A$143,'[1]2050Pop'!$D$7:$D$143) -> India/South Asia | C4: =1000*_xlfn.XLOOKUP(A4,'[1]2050Pop'!$A$7:$A$143,'[1]2050Pop'!$C$7:$C$143) -> 55955 | D4: Bananas | E4: 3.371 | F4: =C4*E4/1000000 -> 0.1886243 | G4: =_xlfn.XLOOKUP(D4,'[1]2050 BAU Mapping to T & C'!$A$3:$A$52,'[1]2050 BAU Mapping to T & C'!$B$3:$B$52) -> Tropical Fruits | H4: =_xlfn.XLOOKUP(G4,'[1]T&C emissions for 2050 analysis'!$B$3:$B$23,'[1]T&C emissions for 2050 analysis'!$C$3:$C$23) -> 0.51333333 | I4: =F4*H4 -> 0.096827143 | J4: =E4*H4 -> 1.7304467
A5: Albania | B5: =_xlfn.XLOOKUP(A5,'[1]2050Pop'!$A$7:$A$143,'[1]2050Pop'!$D$7:$D$143) -> Euro/AU/NZ | C5: =1000*_xlfn.XLOOKUP(A5,'[1]2050Pop'!$A$7:$A$143,'[1]2050Pop'!$C$7:$C$143) -> 2710 | D5: Bananas | E5: 9.711 | F5: =C5*E5/1000000 -> 0.02631681 | G5: =_xlfn.XLOOKUP(D5,'[1]2050 BAU Mapping to T & C'!$A$3:$A$52,'[1]2050 BAU Mapping to T & C'!$B$3:$B$52) -> Tropical Fruits | H5: =_xlfn.XLOOKUP(G5,'[1]T&C emissions for 2050 analysis'!$B$3:$B$23,'[1]T&C emissions for 2050 analysis'!$C$3:$C$23) -> 0.51333333 | I5: =F5*H5 -> 0.013509296 | J5: =E5*H5 -> 4.98498
A6: Algeria | B6: =_xlfn.XLOOKUP(A6,'[1]2050Pop'!$A$7:$A$143,'[1]2050Pop'!$D$7:$D$143) -> MENA | C6: =1000*_xlfn.XLOOKUP(A6,'[1]2050Pop'!$A$7:$A$143,'[1]2050Pop'!$C$7:$C$143) -> 56461 | D6: Bananas | E6: 9.752 | F6: =C6*E6/1000000 -> 0.55060767 | G6: =_xlfn.XLOOKUP(D6,'[1]2050 BAU Mapping to T & C'!$A$3:$A$52,'[1]2050 BAU Mapping to T & C'!$B$3:$B$52) -> Tropical Fruits | H6: =_xlfn.XLOOKUP(G6,'[1]T&C emissions for 2050 analysis'!$B$3:$B$23,'[1]T&C emissions for 2050 analysis'!$C$3:$C$23) -> 0.51333333 | I6: =F6*H6 -> 0.28264527 | J6: =E6*H6 -> 5.0060267
A7: Angola | B7: =_xlfn.XLOOKUP(A7,'[1]2050Pop'!$A$7:$A$143,'[1]2050Pop'!$D$7:$D$143) -> SSA | C7: =1000*_xlfn.XLOOKUP(A7,'[1]2050Pop'!$A$7:$A$143,'[1]2050Pop'!$C$7:$C$143) -> 65473 | D7: Bananas | E7: 73.655 | F7: =C7*E7/1000000 -> 4.8224138 | G7: =_xlfn.XLOOKUP(D7,'[1]2050 BAU Mapping to T & C'!$A$3:$A$52,'[1]2050 BAU Mapping to T & C'!$B$3:$B$52) -> Tropical Fruits | H7: =_xlfn.XLOOKUP(G7,'[1]T&C emissions for 2050 analysis'!$B$3:$B$23,'[1]T&C emissions for 2050 analysis'!$C$3:$C$23) -> 0.51333333 | I7: =F7*H7 -> 2.4755058 | J7: =E7*H7 -> 37.809567
A8: Argentina | B8: =_xlfn.XLOOKUP(A8,'[1]2050Pop'!$A$7:$A$143,'[1]2050Pop'!$D$7:$D$143) -> LatAm & RSA | C8: =1000*_xlfn.XLOOKUP(A8,'[1]2050Pop'!$A$7:$A$143,'[1]2050Pop'!$C$7:$C$143) -> 55445 | D8: Bananas | E8: 22.831 | F8: =C8*E8/1000000 -> 1.2658648 | G8: =_xlfn.XLOOKUP(D8,'[1]2050 BAU Mapping to T & C'!$A$3:$A$52,'[1]2050 BAU Mapping to T & C'!$B$3:$B$52) -> Tropical Fruits | H8: =_xlfn.XLOOKUP(G8,'[1]T&C emissions for 2050 analysis'!$B$3:$B$23,'[1]T&C emissions for 2050 analysis'!$C$3:$C$23) -> 0.51333333 | I8: =F8*H8 -> 0.64981059 | J8: =E8*H8 -> 11.719913
A9: Armenia | B9: =_xlfn.XLOOKUP(A9,'[1]2050Pop'!$A$7:$A$143,'[1]2050Pop'!$D$7:$D$143) -> MENA | C9: =1000*_xlfn.XLOOKUP(A9,'[1]2050Pop'!$A$7:$A$143,'[1]2050Pop'!$C$7:$C$143) -> 2729 | D9: Bananas | E9: 5.225 | F9: =C9*E9/1000000 -> 0.014259025 | G9: =_xlfn.XLOOKUP(D9,'[1]2050 BAU Mapping to T & C'!$A$3:$A$52,'[1]2050 BAU Mapping to T & C'!$B$3:$B$52) -> Tropical Fruits | H9: =_xlfn.XLOOKUP(G9,'[1]T&C emissions for 2050 analysis'!$B$3:$B$23,'[1]T&C emissions for 2050 analysis'!$C$3:$C$23) -> 0.51333333 | I9: =F9*H9 -> 0.0073196328 | J9: =E9*H9 -> 2.6821667
A10: Australia | B10: =_xlfn.XLOOKUP(A10,'[1]2050Pop'!$A$7:$A$143,'[1]2050Pop'!$D$7:$D$143) -> Euro/AU/NZ | C10: =1000*_xlfn.XLOOKUP(A10,'[1]2050Pop'!$A$7:$A$143,'[1]2050Pop'!$C$7:$C$143) -> 33496 | D10: Bananas | E10: 20.676 | F10: =C10*E10/1000000 -> 0.6925633 | G10: =_xlfn.XLOOKUP(D10,'[1]2050 BAU Mapping to T & C'!$A$3:$A$52,'[1]2050 BAU Mapping to T & C'!$B$3:$B$52) -> Tropical Fruits | H10: =_xlfn.XLOOKUP(G10,'[1]T&C emissions for 2050 analysis'!$B$3:$B$23,'[1]T&C emissions for 2050 analysis'!$C$3:$C$23) -> 0.51333333 | I10: =F10*H10 -> 0.35551583 | J10: =E10*H10 -> 10.61368
A11: Austria | B11: =_xlfn.XLOOKUP(A11,'[1]2050Pop'!$A$7:$A$143,'[1]2050Pop'!$D$7:$D$143) -> Euro/AU/NZ | C11: =1000*_xlfn.XLOOKUP(A11,'[1]2050Pop'!$A$7:$A$143,'[1]2050Pop'!$C$7:$C$143) -> 8846 | D11: Bananas | E11: 18.402 | F11: =C11*E11/1000000 -> 0.16278409 | G11: =_xlfn.XLOOKUP(D11,'[1]2050 BAU Mapping to T & C'!$A$3:$A$52,'[1]2050 BAU Mapping to T & C'!$B$3:$B$52) -> Tropical Fruits | H11: =_xlfn.XLOOKUP(G11,'[1]T&C emissions for 2050 analysis'!$B$3:$B$23,'[1]T&C emissions for 2050 analysis'!$C$3:$C$23) -> 0.51333333 | I11: =F11*H11 -> 0.083562501 | J11: =E11*H11 -> 9.44636
A12: Azerbaijan | B12: =_xlfn.XLOOKUP(A12,'[1]2050Pop'!$A$7:$A$143,'[1]2050Pop'!$D$7:$D$143) -> MENA | C12: =1000*_xlfn.XLOOKUP(A12,'[1]2050Pop'!$A$7:$A$143,'[1]2050Pop'!$C$7:$C$143) -> 10963 | D12: Bananas | E12: 2.817 | F12: =C12*E12/1000000 -> 0.030882771 | G12: =_xlfn.XLOOKUP(D12,'[1]2050 BAU Mapping to T & C'!$A$3:$A$52,'[1]2050 BAU Mapping to T & C'!$B$3:$B$52) -> Tropical Fruits | H12: =_xlfn.XLOOKUP(G12,'[1]T&C emissions for 2050 analysis'!$B$3:$B$23,'[1]T&C emissions for 2050 analysis'!$C$3:$C$23) -> 0.51333333 | I12: =F12*H12 -> 0.015853156 | J12: =E12*H12 -> 1.44606
A13: Bangladesh | B13: =_xlfn.XLOOKUP(A13,'[1]2050Pop'!$A$7:$A$143,'[1]2050Pop'!$D$7:$D$143) -> India/South Asia | C13: =1000*_xlfn.XLOOKUP(A13,'[1]2050Pop'!$A$7:$A$143,'[1]2050Pop'!$C$7:$C$143) -> 202209 | D13: Bananas | E13: 9.448 | F13: =C13*E13/1000000 -> 1.9104706 | G13: =_xlfn.XLOOKUP(D13,'[1]2050 BAU Mapping to T & C'!$A$3:$A$52,'[1]2050 BAU Mapping to T & C'!$B$3:$B$52) -> Tropical Fruits | H13: =_xlfn.XLOOKUP(G13,'[1]T&C emissions for 2050 analysis'!$B$3:$B$23,'[1]T&C emissions for 2050 analysis'!$C$3:$C$23) -> 0.51333333 | I13: =F13*H13 -> 0.98070826 | J13: =E13*H13 -> 4.8499733
A14: Belarus | B14: =_xlfn.XLOOKUP(A14,'[1]2050Pop'!$A$7:$A$143,'[1]2050Pop'!$D$7:$D$143) -> Euro/AU/NZ | C14: =1000*_xlfn.XLOOKUP(A14,'[1]2050Pop'!$A$7:$A$143,'[1]2050Pop'!$C$7:$C$143) -> 8125 | D14: Bananas | E14: 10.937 | F14: =C14*E14/1000000 -> 0.088863125 | G14: =_xlfn.XLOOKUP(D14,'[1]2050 BAU Mapping to T & C'!$A$3:$A$52,'[1]2050 BAU Mapping to T & C'!$B$3:$B$52) -> Tropical Fruits | H14: =_xlfn.XLOOKUP(G14,'[1]T&C emissions for 2050 analysis'!$B$3:$B$23,'[1]T&C emissions for 2050 analysis'!$C$3:$C$23) -> 0.51333333 | I14: =F14*H14 -> 0.045616404 | J14: =E14*H14 -> 5.6143267
A15: Belgium | B15: =_xlfn.XLOOKUP(A15,'[1]2050Pop'!$A$7:$A$143,'[1]2050Pop'!$D$7:$D$143) -> Euro/AU/NZ | C15: =1000*_xlfn.XLOOKUP(A15,'[1]2050Pop'!$A$7:$A$143,'[1]2050Pop'!$C$7:$C$143) -> 12527 | D15: Bananas | E15: 7.947 | F15: =C15*E15/1000000 -> 0.099552069 | G15: =_xlfn.XLOOKUP(D15,'[1]2050 BAU Mapping to T & C'!$A$3:$A$52,'[1]2050 BAU Mapping to T & C'!$B$3:$B$52) -> Tropical Fruits | H15: =_xlfn.XLOOKUP(G15,'[1]T&C emissions for 2050 analysis'!$B$3:$B$23,'[1]T&C emissions for 2050 analysis'!$C$3:$C$23) -> 0.51333333 | I15: =F15*H15 -> 0.051103395 | J15: =E15*H15 -> 4.07946
... A4620: Zimbabwe | B4620: =_xlfn.XLOOKUP(A4620,'[1]2050Pop'!$A$7:$A$143,'[1]2050Pop'!$D$7:$D$143) -> SSA | C4620: =1000*_xlfn.XLOOKUP(A4620,'[1]2050Pop'!$A$7:$A$143,'[1]2050Pop'!$C$7:$C$143) -> 29615 | D4620: Wheat | E4620: 327.814 | F4620: =C4620*E4620/1000000 -> 9.7082116 | G4620: =_xlfn.XLOOKUP(D4620,'[1]2050 BAU Mapping to T & C'!$A$3:$A$52,'[1]2050 BAU Mapping to T & C'!$B$3:$B$52) -> Wheat | H4620: =_xlfn.XLOOKUP(G4620,'[1]T&C emissions for 2050 analysis'!$B$3:$B$23,'[1]T&C emissions for 2050 analysis'!$C$3:$C$23) -> 0.22 | I4620: =F4620*H4620 -> 2.1358066 | J4620: =E4620*H4620 -> 72.11908

Sheet Emissions (IDN)
A1: Scenario | B1: Year | C1: Region | D1: Commodity group | E1: Commodity | F1: FSC1 Emissions | G1: FSC2 Emissions | H1: FSC3 Emissions | I1: FSC4 Emissions | J1: FSC5 Emissions | K1: Total (1000 tonnes) | L1: FSC1 Emissions (Mt) | M1: FSC2 Emissions (Mt) | N1: FSC3 Emissions (Mt) | O1: FSC4 Emissions (Mt) | P1: FSC5 Emissions (Mt) | Q1: Total Emissions (Mt)
A2: 2020 | B2: 2020 | C2: Indonesia | D2: Cereals | E2: Barley | F2: ='Food loss and waste (IDN)'!F2*'Emissions factors'!$D$102 -> 0 | G2: ='Food loss and waste (IDN)'!G2*'Emissions factors'!$D$102 -> 8.1057 | H2: ='Food loss and waste (IDN)'!H2*'Emissions factors'!$D$102 -> 8.042601 | I2: ='Food loss and waste (IDN)'!I2*'Emissions factors'!$D$102 -> 3.1841806 | J2: ='Food loss and waste (IDN)'!J2*'Emissions factors'!$D$102 -> 3.1100256 | K2: =SUM(F2:J2) -> 22.442507 | L2: =F2/1000 -> 0 | M2: =G2/1000 -> 0.0081057 | N2: =H2/1000 -> 0.008042601 | O2: =I2/1000 -> 0.0031841806 | P2: =J2/1000 -> 0.0031100256 | Q2: =SUM(L2:P2) -> 0.022442507
A3: 2020 | B3: 2020 | C3: Indonesia | D3: Cereals | E3: Maize | F3: ='Food loss and waste (IDN)'!F3*'Emissions factors'!$D$103 -> 115.89627 | G3: ='Food loss and waste (IDN)'!G3*'Emissions factors'!$D$103 -> 123.24247 | H3: ='Food loss and waste (IDN)'!H3*'Emissions factors'!$D$103 -> 122.28309 | I3: ='Food loss and waste (IDN)'!I3*'Emissions factors'!$D$103 -> 48.413621 | J3: ='Food loss and waste (IDN)'!J3*'Emissions factors'!$D$103 -> 47.286136 | K3: =SUM(F3:J3) -> 457.12159 | L3: =F3/1000 -> 0.11589627 | M3: =G3/1000 -> 0.12324247 | N3: =H3/1000 -> 0.12228309 | O3: =I3/1000 -> 0.048413621 | P3: =J3/1000 -> 0.047286136 | Q3: =SUM(L3:P3) -> 0.45712159
A4: 2020 | B4: 2020 | C4: Indonesia | D4: Cereals | E4: Millet | F4: ='Food loss and waste (IDN)'!F4*'Emissions factors'!$D$104 -> 0 | G4: ='Food loss and waste (IDN)'!G4*'Emissions factors'!$D$104 -> 1.409601 | H4: ='Food loss and waste (IDN)'!H4*'Emissions factors'!$D$104 -> 1.3986279 | I4: ='Food loss and waste (IDN)'!I4*'Emissions factors'!$D$104 -> 0.55373678 | J4: ='Food loss and waste (IDN)'!J4*'Emissions factors'!$D$104 -> 0.54084103 | K4: =SUM(F4:J4) -> 3.9028067 | L4: =F4/1000 -> 0 | M4: =G4/1000 -> 0.001409601 | N4: =H4/1000 -> 0.0013986279 | O4: =I4/1000 -> 0.00055373678 | P4: =J4/1000 -> 0.00054084103 | Q4: =SUM(L4:P4) -> 0.0039028067
A5: 2020 | B5: 2020 | C5: Indonesia | D5: Cereals | E5: Oats | F5: ='Food loss and waste (IDN)'!F5*'Emissions factors'!$D$105 -> 0 | G5: ='Food loss and waste (IDN)'!G5*'Emissions factors'!$D$105 -> 1.041879 | H5: ='Food loss and waste (IDN)'!H5*'Emissions factors'!$D$105 -> 1.0337685 | I5: ='Food loss and waste (IDN)'!I5*'Emissions factors'!$D$105 -> 0.40928371 | J5: ='Food loss and waste (IDN)'!J5*'Emissions factors'!$D$105 -> 0.39975206 | K5: =SUM(F5:J5) -> 2.8846832 | L5: =F5/1000 -> 0 | M5: =G5/1000 -> 0.001041879 | N5: =H5/1000 -> 0.0010337685 | O5: =I5/1000 -> 0.00040928371 | P5: =J5/1000 -> 0.00039975206 | Q5: =SUM(L5:P5) -> 0.0028846832
A6: 2020 | B6: 2020 | C6: Indonesia | D6: Cereals | E6: Other cereals | F6: ='Food loss and waste (IDN)'!F6*'Emissions factors'!$D$110 -> 0.0186 | G6: ='Food loss and waste (IDN)'!G6*'Emissions factors'!$D$110 -> 0.06006126 | H6: ='Food loss and waste (IDN)'!H6*'Emissions factors'!$D$110 -> 0.059593712 | I6: ='Food loss and waste (IDN)'!I6*'Emissions factors'!$D$110 -> 0.023594002 | J6: ='Food loss and waste (IDN)'!J6*'Emissions factors'!$D$110 -> 0.023044531 | K6: =SUM(F6:J6) -> 0.1848935 | L6: =F6/1000 -> 1.86e-05 | M6: =G6/1000 -> 6.006126e-05 | N6: =H6/1000 -> 5.9593712e-05 | O6: =I6/1000 -> 2.3594002e-05 | P6: =J6/1000 -> 2.3044531e-05 | Q6: =SUM(L6:P6) -> 0.0001848935
A7: 2020 | B7: 2020 | C7: Indonesia | D7: Cereals | E7: Rice | F7: ='Food loss and waste (IDN)'!F7*'Emissions factors'!$D$106 -> 6027.8994 | G7: ='Food loss and waste (IDN)'!G7*'Emissions factors'!$D$106 -> 6518.8854 | H7: ='Food loss and waste (IDN)'!H7*'Emissions factors'!$D$106 -> 6468.139 | I7: ='Food loss and waste (IDN)'!I7*'Emissions factors'!$D$106 -> 2560.8286 | J7: ='Food loss and waste (IDN)'!J7*'Emissions factors'!$D$106 -> 2501.1905 | K7: =SUM(F7:J7) -> 24076.943 | L7: =F7/1000 -> 6.0278994 | M7: =G7/1000 -> 6.5188854 | N7: =H7/1000 -> 6.468139 | O7: =I7/1000 -> 2.5608286 | P7: =J7/1000 -> 2.5011905 | Q7: =SUM(L7:P7) -> 24.076943
A8: 2020 | B8: 2020 | C8: Indonesia | D8: Cereals | E8: Rye | F8: - | G8: - | H8: - | I8: - | J8: - | K8: - | L8: - | M8: - | N8: - | O8: - | P8: - | Q8: -
A9: 2020 | B9: 2020 | C9: Indonesia | D9: Cereals | E9: Sorghum | F9: - | G9: - | H9: - | I9: - | J9: - | K9: - | L9: - | M9: - | N9: - | O9: - | P9: - | Q9: -
A10: 2020 | B10: 2020 | C10: Indonesia | D10: Cereals | E10: Wheat | F10: ='Food loss and waste (IDN)'!F10*'Emissions factors'!$D$109 -> 0 | G10: ='Food loss and waste (IDN)'!G10*'Emissions factors'!$D$109 -> 291.8031 | H10: ='Food loss and waste (IDN)'!H10*'Emissions factors'!$D$109 -> 289.53155 | I10: ='Food loss and waste (IDN)'!I10*'Emissions factors'!$D$109 -> 114.62968 | J10: ='Food loss and waste (IDN)'!J10*'Emissions factors'!$D$109 -> 111.96011 | K10: =SUM(F10:J10) -> 807.92445 | L10: =F10/1000 -> 0 | M10: =G10/1000 -> 0.2918031 | N10: =H10/1000 -> 0.28953155 | O10: =I10/1000 -> 0.11462968 | P10: =J10/1000 -> 0.11196011 | Q10: =SUM(L10:P10) -> 0.80792445
A11: 2020 | B11: 2020 | C11: Indonesia | D11: Fruits & Vegetables | E11: Apples | F11: ='Food loss and waste (IDN)'!F11*'Emissions factors'!$D$111 -> 4.530942 | G11: ='Food loss and waste (IDN)'!G11*'Emissions factors'!$D$111 -> 4.68717 | H11: ='Food loss and waste (IDN)'!H11*'Emissions factors'!$D$111 -> 10.700472 | I11: ='Food loss and waste (IDN)'!I11*'Emissions factors'!$D$111 -> 4.1603435 | J11: ='Food loss and waste (IDN)'!J11*'Emissions factors'!$D$111 -> 5.0740988 | K11: =SUM(F11:J11) -> 29.153026 | L11: =F11/1000 -> 0.004530942 | M11: =G11/1000 -> 0.00468717 | N11: =H11/1000 -> 0.010700472 | O11: =I11/1000 -> 0.0041603435 | P11: =J11/1000 -> 0.0050740988 | Q11: =SUM(L11:P11) -> 0.029153026
A12: 2020 | B12: 2020 | C12: Indonesia | D12: Fruits & Vegetables | E12: Bananas | F12: ='Food loss and waste (IDN)'!F12*'Emissions factors'!$D$112 -> 320.73269 | G12: ='Food loss and waste (IDN)'!G12*'Emissions factors'!$D$112 -> 331.43631 | H12: ='Food loss and waste (IDN)'!H12*'Emissions factors'!$D$112 -> 756.64525 | I12: ='Food loss and waste (IDN)'!I12*'Emissions factors'!$D$112 -> 294.18367 | J12: ='Food loss and waste (IDN)'!J12*'Emissions factors'!$D$112 -> 358.79658 | K12: =SUM(F12:J12) -> 2061.7945 | L12: =F12/1000 -> 0.32073269 | M12: =G12/1000 -> 0.33143631 | N12: =H12/1000 -> 0.75664525 | O12: =I12/1000 -> 0.29418367 | P12: =J12/1000 -> 0.35879658 | Q12: =SUM(L12:P12) -> 2.0617945
A13: 2020 | B13: 2020 | C13: Indonesia | D13: Fruits & Vegetables | E13: Citrus | F13: ='Food loss and waste (IDN)'!F13*'Emissions factors'!$D$113 -> 0.180297 | G13: ='Food loss and waste (IDN)'!G13*'Emissions factors'!$D$113 -> 0.18651369 | H13: ='Food loss and waste (IDN)'!H13*'Emissions factors'!$D$113 -> 0.42579733 | I13: ='Food loss and waste (IDN)'!I13*'Emissions factors'!$D$113 -> 0.16555 | J13: ='Food loss and waste (IDN)'!J13*'Emissions factors'!$D$113 -> 0.2019105 | K13: =SUM(F13:J13) -> 1.1600685 | L13: =F13/1000 -> 0.000180297 | M13: =G13/1000 -> 0.00018651369 | N13: =H13/1000 -> 0.00042579733 | O13: =I13/1000 -> 0.00016555 | P13: =J13/1000 -> 0.0002019105 | Q13: =SUM(L13:P13) -> 0.0011600685
A14: 2020 | B14: 2020 | C14: Indonesia | D14: Fruits & Vegetables | E14: Grapes | F14: ='Food loss and waste (IDN)'!F14*'Emissions factors'!$D$114 -> 0 | G14: ='Food loss and waste (IDN)'!G14*'Emissions factors'!$D$114 -> 5.691042 | H14: ='Food loss and waste (IDN)'!H14*'Emissions factors'!$D$114 -> 12.992239 | I14: ='Food loss and waste (IDN)'!I14*'Emissions factors'!$D$114 -> 5.0513827 | J14: ='Food loss and waste (IDN)'!J14*'Emissions factors'!$D$114 -> 6.160841 | K14: =SUM(F14:J14) -> 29.895505 | L14: =F14/1000 -> 0 | M14: =G14/1000 -> 0.005691042 | N14: =H14/1000 -> 0.012992239 | O14: =I14/1000 -> 0.0050513827 | P14: =J14/1000 -> 0.006160841 | Q14: =SUM(L14:P14) -> 0.029895505
A15: 2020 | B15: 2020 | C15: Indonesia | D15: Fruits & Vegetables | E15: Other fruits | F15: ='Food loss and waste (IDN)'!F15*'Emissions factors'!$D$115 -> 640.33133 | G15: ='Food loss and waste (IDN)'!G15*'Emissions factors'!$D$115 -> 678.07973 | H15: ='Food loss and waste (IDN)'!H15*'Emissions factors'!$D$115 -> 1548.0072 | I15: ='Food loss and waste (IDN)'!I15*'Emissions factors'!$D$115 -> 601.86521 | J15: ='Food loss and waste (IDN)'!J15*'Emissions factors'!$D$115 -> 734.05562 | K15: =SUM(F15:J15) -> 4202.3391 | L15: =F15/1000 -> 0.64033133 | M15: =G15/1000 -> 0.67807973 | N15: =H15/1000 -> 1.5480072 | O15: =I15/1000 -> 0.60186521 | P15: =J15/1000 -> 0.73405562 | Q15: =SUM(L15:P15) -> 4.2023391
A16: 2020 | B16: 2020 | C16: Indonesia | D16: Fruits & Vegetables | E16: Vegetables | F16: ='Food loss and waste (IDN)'!F16*'Emissions factors'!$D$116 -> 745.08911 | G16: ='Food loss and waste (IDN)'!G16*'Emissions factors'!$D$116 -> 815.87008 | H16: ='Food loss and waste (IDN)'!H16*'Emissions factors'!$D$116 -> 1862.5727 | I16: ='Food loss and waste (IDN)'!I16*'Emissions factors'!$D$116 -> 724.16827 | J16: ='Food loss and waste (IDN)'!J16*'Emissions factors'!$D$116 -> 883.22065 | K16: =SUM(F16:J16) -> 5030.9208 | L16: =F16/1000 -> 0.74508911 | M16: =G16/1000 -> 0.81587008 | N16: =H16/1000 -> 1.8625727 | O16: =I16/1000 -> 0.72416827 | P16: =J16/1000 -> 0.88322065 | Q16: =SUM(L16:P16) -> 5.0309208
A17: 2020 | B17: 2020 | C17: Indonesia | D17: Marine | E17: Fish & Seafood | F17: ='Food loss and waste (IDN)'!F17*'Emissions factors'!$D$117 -> 4277.9782 | G17: ='Food loss and waste (IDN)'!G17*'Emissions factors'!$D$117 -> 11960.957 | H17: ='Food loss and waste (IDN)'!H17*'Emissions factors'!$D$117 -> 3150.0004 | I17: ='Food loss and waste (IDN)'!I17*'Emissions factors'!$D$117 -> 3927.1055 | J17: ='Food loss and waste (IDN)'!J17*'Emissions factors'!$D$117 -> 558.45798 | K17: =SUM(F17:J17) -> 23874.499 | L17: =F17/1000 -> 4.2779782 | M17: =G17/1000 -> 11.960957 | N17: =H17/1000 -> 3.1500004 | O17: =I17/1000 -> 3.9271055 | P17: =J17/1000 -> 0.55845798 | Q17: =SUM(L17:P17) -> 23.874499
A18: 2020 | B18: 2020 | C18: Indonesia | D18: Meat | E18: Bovine meat | F18: ='Food loss and waste (IDN)'!F18*'Emissions factors'!$D$118 -> 1844.576 | G18: ='Food loss and waste (IDN)'!G18*'Emissions factors'!$D$118 -> 53.409854 | H18: ='Food loss and waste (IDN)'!H18*'Emissions factors'!$D$118 -> 1268.9927 | I18: ='Food loss and waste (IDN)'!I18*'Emissions factors'!$D$118 -> 1687.7603 | J18: ='Food loss and waste (IDN)'!J18*'Emissions factors'!$D$118 -> 896.92405 | K18: =SUM(F18:J18) -> 5751.6629 | L18: =F18/1000 -> 1.844576 | M18: =G18/1000 -> 0.053409854 | N18: =H18/1000 -> 1.2689927 | O18: =I18/1000 -> 1.6877603 | P18: =J18/1000 -> 0.89692405 | Q18: =SUM(L18:P18) -> 5.7516629
A19: 2020 | B19: 2020 | C19: Indonesia | D19: Meat | E19: Mutton & Goat | F19: ='Food loss and waste (IDN)'!F19*'Emissions factors'!$D$119 -> 182.236 | G19: ='Food loss and waste (IDN)'!G19*'Emissions factors'!$D$119 -> 3.311668 | H19: ='Food loss and waste (IDN)'!H19*'Emissions factors'!$D$119 -> 82.626117 | I19: ='Food loss and waste (IDN)'!I19*'Emissions factors'!$D$119 -> 109.89274 | J19: ='Food loss and waste (IDN)'!J19*'Emissions factors'!$D$119 -> 58.400139 | K19: =SUM(F19:J19) -> 436.46666 | L19: =F19/1000 -> 0.182236 | M19: =G19/1000 -> 0.003311668 | N19: =H19/1000 -> 0.082626117 | O19: =I19/1000 -> 0.10989274 | P19: =J19/1000 -> 0.058400139 | Q19: =SUM(L19:P19) -> 0.43646666
A20: 2020 | B20: 2020 | C20: Indonesia | D20: Meat | E20: Pigmeat | F20: ='Food loss and waste (IDN)'!F20*'Emissions factors'!$D$120 -> 116.6712 | G20: ='Food loss and waste (IDN)'!G20*'Emissions factors'!$D$120 -> 8.6884614 | H20: ='Food loss and waste (IDN)'!H20*'Emissions factors'!$D$120 -> 91.996017 | I20: ='Food loss and waste (IDN)'!I20*'Emissions factors'!$D$120 -> 122.3547 | J20: ='Food loss and waste (IDN)'!J20*'Emissions factors'!$D$120 -> 65.022785 | K20: =SUM(F20:J20) -> 404.73317 | L20: =F20/1000 -> 0.1166712 | M20: =G20/1000 -> 0.0086884614 | N20: =H20/1000 -> 0.091996017 | O20: =I20/1000 -> 0.1223547 | P20: =J20/1000 -> 0.065022785 | Q20: =SUM(L20:P20) -> 0.40473317
A21: 2020 | B21: 2020 | C21: Indonesia | D21: Meat | E21: Poultry | F21: ='Food loss and waste (IDN)'!F21*'Emissions factors'!$D$121 -> 1034.1864 | G21: ='Food loss and waste (IDN)'!G21*'Emissions factors'!$D$121 -> 76.128596 | H21: ='Food loss and waste (IDN)'!H21*'Emissions factors'!$D$121 -> 806.07225 | I21: ='Food loss and waste (IDN)'!I21*'Emissions factors'!$D$121 -> 1072.0761 | J21: ='Food loss and waste (IDN)'!J21*'Emissions factors'!$D$121 -> 569.73187 | K21: =SUM(F21:J21) -> 3558.1952 | L21: =F21/1000 -> 1.0341864 | M21: =G21/1000 -> 0.076128596 | N21: =H21/1000 -> 0.80607225 | O21: =I21/1000 -> 1.0720761 | P21: =J21/1000 -> 0.56973187 | Q21: =SUM(L21:P21) -> 3.5581952
A22: 2020 | B22: 2020 | C22: Indonesia | D22: Milk & Eggs | E22: Eggs | F22: ='Food loss and waste (IDN)'!F22*'Emissions factors'!$D$122 -> 1178.2194 | G22: ='Food loss and waste (IDN)'!G22*'Emissions factors'!$D$122 -> 981.1819 | H22: ='Food loss and waste (IDN)'!H22*'Emissions factors'!$D$122 -> 12.589799 | I22: ='Food loss and waste (IDN)'!I22*'Emissions factors'!$D$122 -> 377.31627 | J22: ='Food loss and waste (IDN)'!J22*'Emissions factors'!$D$122 -> 243.99785 | K22: =SUM(F22:J22) -> 2793.3052 | L22: =F22/1000 -> 1.1782194 | M22: =G22/1000 -> 0.9811819 | N22: =H22/1000 -> 0.012589799 | O22: =I22/1000 -> 0.37731627 | P22: =J22/1000 -> 0.24399785 | Q22: =SUM(L22:P22) -> 2.7933052
A23: 2020 | B23: 2020 | C23: Indonesia | D23: Milk & Eggs | E23: Milk | F23: ='Food loss and waste (IDN)'!F23*'Emissions factors'!$D$123 -> 62.004142 | G23: ='Food loss and waste (IDN)'!G23*'Emissions factors'!$D$123 -> 478.12583 | H23: ='Food loss and waste (IDN)'!H23*'Emissions factors'!$D$123 -> 194.76476 | I23: ='Food loss and waste (IDN)'!I23*'Emissions factors'!$D$123 -> 954.34733 | J23: ='Food loss and waste (IDN)'!J23*'Emissions factors'!$D$123 -> 85.89126 | K23: =SUM(F23:J23) -> 1775.1333 | L23: =F23/1000 -> 0.062004142 | M23: =G23/1000 -> 0.47812583 | N23: =H23/1000 -> 0.19476476 | O23: =I23/1000 -> 0.95434733 | P23: =J23/1000 -> 0.08589126 | Q23: =SUM(L23:P23) -> 1.7751333
A24: 2020 | B24: 2020 | C24: Indonesia | D24: Oil crops & Pulses | E24: Oil crops | F24: ='Food loss and waste (IDN)'!F24*'Emissions factors'!$D$124 -> 26.622974 | G24: ='Food loss and waste (IDN)'!G24*'Emissions factors'!$D$124 -> 12.222899 | H24: ='Food loss and waste (IDN)'!H24*'Emissions factors'!$D$124 -> 27.78193 | I24: ='Food loss and waste (IDN)'!I24*'Emissions factors'!$D$124 -> 6.3898439 | J24: ='Food loss and waste (IDN)'!J24*'Emissions factors'!$D$124 -> 3.1310235 | K24: =SUM(F24:J24) -> 76.148671 | L24: =F24/1000 -> 0.026622974 | M24: =G24/1000 -> 0.012222899 | N24: =H24/1000 -> 0.02778193 | O24: =I24/1000 -> 0.0063898439 | P24: =J24/1000 -> 0.0031310235 | Q24: =SUM(L24:P24) -> 0.076148671
A25: 2020 | B25: 2020 | C25: Indonesia | D25: Oil crops & Pulses | E25: Pulses | F25: ='Food loss and waste (IDN)'!F25*'Emissions factors'!$D$125 -> 0.069236364 | G25: ='Food loss and waste (IDN)'!G25*'Emissions factors'!$D$125 -> 0.18260596 | H25: ='Food loss and waste (IDN)'!H25*'Emissions factors'!$D$125 -> 0.41505261 | I25: ='Food loss and waste (IDN)'!I25*'Emissions factors'!$D$125 -> 0.095462101 | J25: ='Food loss and waste (IDN)'!J25*'Emissions factors'!$D$125 -> 0.04677643 | K25: =SUM(F25:J25) -> 0.80913347 | L25: =F25/1000 -> 6.9236364e-05 | M25: =G25/1000 -> 0.00018260596 | N25: =H25/1000 -> 0.00041505261 | O25: =I25/1000 -> 9.5462101e-05 | P25: =J25/1000 -> 4.677643e-05 | Q25: =SUM(L25:P25) -> 0.00080913347
A26: 2020 | B26: 2020 | C26: Indonesia | D26: Roots & Tubers | E26: Starchy Roots | F26: ='Food loss and waste (IDN)'!F26*'Emissions factors'!$D$126 -> 4.2865378 | G26: ='Food loss and waste (IDN)'!G26*'Emissions factors'!$D$126 -> 5.1367188 | H26: ='Food loss and waste (IDN)'!H26*'Emissions factors'!$D$126 -> 3.7280447 | I26: ='Food loss and waste (IDN)'!I26*'Emissions factors'!$D$126 -> 3.616949 | J26: ='Food loss and waste (IDN)'!J26*'Emissions factors'!$D$126 -> 1.1614956 | K26: =SUM(F26:J26) -> 17.929746 | L26: =F26/1000 -> 0.0042865378 | M26: =G26/1000 -> 0.0051367188 | N26: =H26/1000 -> 0.0037280447 | O26: =I26/1000 -> 0.003616949 | P26: =J26/1000 -> 0.0011614956 | Q26: =SUM(L26:P26) -> 0.017929746
A27: 2050 | B27: 2050 | C27: Indonesia | D27: Cereals | E27: Barley | F27: - | G27: - | H27: - | I27: - | J27: - | K27: - | L27: - | M27: - | N27: - | O27: - | P27: - | Q27: -
A28: 2050 | B28: 2050 | C28: Indonesia | D28: Cereals | E28: Maize | F28: ='Food loss and waste (IDN)'!F28*'Emissions factors'!$D$103 -> 187.01865 | G28: ='Food loss and waste (IDN)'!G28*'Emissions factors'!$D$103 -> 198.87302 | H28: ='Food loss and waste (IDN)'!H28*'Emissions factors'!$D$103 -> 197.32489 | I28: ='Food loss and waste (IDN)'!I28*'Emissions factors'!$D$103 -> 78.123742 | J28: ='Food loss and waste (IDN)'!J28*'Emissions factors'!$D$103 -> 76.30435 | K28: =SUM(F28:J28) -> 737.64465 | L28: =F28/1000 -> 0.18701865 | M28: =G28/1000 -> 0.19887302 | N28: =H28/1000 -> 0.19732489 | O28: =I28/1000 -> 0.078123742 | P28: =J28/1000 -> 0.07630435 | Q28: =SUM(L28:P28) -> 0.73764465
A29: 2050 | B29: 2050 | C29: Indonesia | D29: Cereals | E29: Millet | F29: - | G29: - | H29: - | I29: - | J29: - | K29: - | L29: - | M29: - | N29: - | O29: - | P29: - | Q29: -
A30: 2050 | B30: 2050 | C30: Indonesia | D30: Cereals | E30: Oats | F30: - | G30: - | H30: - | I30: - | J30: - | K30: - | L30: - | M30: - | N30: - | O30: - | P30: - | Q30: -
A31: 2050 | B31: 2050 | C31: Indonesia | D31: Cereals | E31: Other cereals | F31: - | G31: - | H31: - | I31: - | J31: - | K31: - | L31: - | M31: - | N31: - | O31: - | P31: - | Q31: -
A32: 2050 | B32: 2050 | C32: Indonesia | D32: Cereals | E32: Rice | F32: ='Food loss and waste (IDN)'!F32*'Emissions factors'!$D$106 -> 6175.8118 | G32: ='Food loss and waste (IDN)'!G32*'Emissions factors'!$D$106 -> 6678.8456 | H32: ='Food loss and waste (IDN)'!H32*'Emissions factors'!$D$106 -> 6626.854 | I32: ='Food loss and waste (IDN)'!I32*'Emissions factors'!$D$106 -> 2623.6662 | J32: ='Food loss and waste (IDN)'!J32*'Emissions factors'!$D$106 -> 2562.5647 | K32: =SUM(F32:J32) -> 24667.742 | L32: =F32/1000 -> 6.1758118 | M32: =G32/1000 -> 6.6788456 | N32: =H32/1000 -> 6.626854 | O32: =I32/1000 -> 2.6236662 | P32: =J32/1000 -> 2.5625647 | Q32: =SUM(L32:P32) -> 24.667742
A33: 2050 | B33: 2050 | C33: Indonesia | D33: Cereals | E33: Rye | F33: - | G33: - | H33: - | I33: - | J33: - | K33: - | L33: - | M33: - | N33: - | O33: - | P33: - | Q33: -
A34: 2050 | B34: 2050 | C34: Indonesia | D34: Cereals | E34: Sorghum | F34: - | G34: - | H34: - | I34: - | J34: - | K34: - | L34: - | M34: - | N34: - | O34: - | P34: - | Q34: -
A35: 2050 | B35: 2050 | C35: Indonesia | D35: Cereals | E35: Wheat | F35: - | G35: - | H35: - | I35: - | J35: - | K35: - | L35: - | M35: - | N35: - | O35: - | P35: - | Q35: -
A36: 2050 | B36: 2050 | C36: Indonesia | D36: Fruits & Vegetables | E36: Apples | F36: - | G36: - | H36: - | I36: - | J36: - | K36: - | L36: - | M36: - | N36: - | O36: - | P36: - | Q36: -
A37: 2050 | B37: 2050 | C37: Indonesia | D37: Fruits & Vegetables | E37: Bananas | F37: ='Food loss and waste (IDN)'!F37*'Emissions factors'!$D$112 -> 328.44015 | G37: ='Food loss and waste (IDN)'!G37*'Emissions factors'!$D$112 -> 339.40099 | H37: ='Food loss and waste (IDN)'!H37*'Emissions factors'!$D$112 -> 774.82804 | I37: ='Food loss and waste (IDN)'!I37*'Emissions factors'!$D$112 -> 301.25314 | J37: ='Food loss and waste (IDN)'!J37*'Emissions factors'!$D$112 -> 367.41875 | K37: =SUM(F37:J37) -> 2111.3411 | L37: =F37/1000 -> 0.32844015 | M37: =G37/1000 -> 0.33940099 | N37: =H37/1000 -> 0.77482804 | O37: =I37/1000 -> 0.30125314 | P37: =J37/1000 -> 0.36741875 | Q37: =SUM(L37:P37) -> 2.1113411
A38: 2050 | B38: 2050 | C38: Indonesia | D38: Fruits & Vegetables | E38: Citrus | F38: ='Food loss and waste (IDN)'!F38*'Emissions factors'!$D$113 -> 37.198897 | G38: ='Food loss and waste (IDN)'!G38*'Emissions factors'!$D$113 -> 38.481524 | H38: ='Food loss and waste (IDN)'!H38*'Emissions factors'!$D$113 -> 87.850552 | I38: ='Food loss and waste (IDN)'!I38*'Emissions factors'!$D$113 -> 34.156295 | J38: ='Food loss and waste (IDN)'!J38*'Emissions factors'!$D$113 -> 41.658198 | K38: =SUM(F38:J38) -> 239.34547 | L38: =F38/1000 -> 0.037198897 | M38: =G38/1000 -> 0.038481524 | N38: =H38/1000 -> 0.087850552 | O38: =I38/1000 -> 0.034156295 | P38: =J38/1000 -> 0.041658198 | Q38: =SUM(L38:P38) -> 0.23934547
A39: 2050 | B39: 2050 | C39: Indonesia | D39: Fruits & Vegetables | E39: Grapes | F39: - | G39: - | H39: - | I39: - | J39: - | K39: - | L39: - | M39: - | N39: - | O39: - | P39: - | Q39: -
A40: 2050 | B40: 2050 | C40: Indonesia | D40: Fruits & Vegetables | E40: Other fruits | F40: ='Food loss and waste (IDN)'!F40*'Emissions factors'!$D$115 -> 11.513233 | G40: ='Food loss and waste (IDN)'!G40*'Emissions factors'!$D$115 -> 12.191954 | H40: ='Food loss and waste (IDN)'!H40*'Emissions factors'!$D$115 -> 27.833354 | I40: ='Food loss and waste (IDN)'!I40*'Emissions factors'!$D$115 -> 10.821608 | J40: ='Food loss and waste (IDN)'!J40*'Emissions factors'!$D$115 -> 13.198407 | K40: =SUM(F40:J40) -> 75.558557 | L40: =F40/1000 -> 0.011513233 | M40: =G40/1000 -> 0.012191954 | N40: =H40/1000 -> 0.027833354 | O40: =I40/1000 -> 0.010821608 | P40: =J40/1000 -> 0.013198407 | Q40: =SUM(L40:P40) -> 0.075558557
...

Sheet Food loss and waste (IDN)
A1: Scenario | B1: Year | C1: Region | D1: Commodity group | E1: Commodity | F1: FSC1 FLW | G1: FSC2 FLW | H1: FSC3 FLW | I1: FSC4 FLW | J1: FSC5 FLW | K1: Total (1000 tonnes) | L1: FSC1 FLW (Mt) | M1: FSC2 FLW (Mt) | N1: FSC3 FLW (Mt) | O1: FSC4 FLW (Mt) | P1: FSC5 FLW (Mt) | Q1: Total (Mt)
A2: 2020 | B2: 2020 | C2: Indonesia | D2: Cereals | E2: Barley | F2: ='FSC data (IDN)'!O2*('Loss factors'!$E$68/100) -> 0 | G2: ='FSC data (IDN)'!P2*('Loss factors'!$F$68/100) -> 10.8076 | H2: ='FSC data (IDN)'!Q2*('Loss factors'!$G$68/100) -> 10.723468 | I2: ='FSC data (IDN)'!R2*('Loss factors'!$H$68/100) -> 4.2455742 | J2: ='FSC data (IDN)'!S2*('Loss factors'!$I$68/100) -> 4.1467007 | K2: =SUM(F2:J2) -> 29.923343 | L2: =F2/1000 -> 0 | M2: =G2/1000 -> 0.0108076 | N2: =H2/1000 -> 0.010723468 | O2: =I2/1000 -> 0.0042455742 | P2: =J2/1000 -> 0.0041467007 | Q2: =SUM(L2:P2) -> 0.029923343
A3: 2020 | B3: 2020 | C3: Indonesia | D3: Cereals | E3: Maize | F3: ='FSC data (IDN)'!O3*('Loss factors'!$E$68/100) -> 66.992063 | G3: ='FSC data (IDN)'!P3*('Loss factors'!$F$68/100) -> 71.238423 | H3: ='FSC data (IDN)'!Q3*('Loss factors'!$G$68/100) -> 70.683866 | I3: ='FSC data (IDN)'!R3*('Loss factors'!$H$68/100) -> 27.984752 | J3: ='FSC data (IDN)'!S3*('Loss factors'!$I$68/100) -> 27.333027 | K3: =SUM(F3:J3) -> 264.23213 | L3: =F3/1000 -> 0.066992063 | M3: =G3/1000 -> 0.071238423 | N3: =H3/1000 -> 0.070683866 | O3: =I3/1000 -> 0.027984752 | P3: =J3/1000 -> 0.027333027 | Q3: =SUM(L3:P3) -> 0.26423213
A4: 2020 | B4: 2020 | C4: Indonesia | D4: Cereals | E4: Millet | F4: ='FSC data (IDN)'!O4*('Loss factors'!$E$68/100) -> 0 | G4: ='FSC data (IDN)'!P4*('Loss factors'!$F$68/100) -> 1.5157 | H4: ='FSC data (IDN)'!Q4*('Loss factors'!$G$68/100) -> 1.503901 | I4: ='FSC data (IDN)'!R4*('Loss factors'!$H$68/100) -> 0.59541589 | J4: ='FSC data (IDN)'!S4*('Loss factors'!$I$68/100) -> 0.58154949 | K4: =SUM(F4:J4) -> 4.1965664 | L4: =F4/1000 -> 0 | M4: =G4/1000 -> 0.0015157 | N4: =H4/1000 -> 0.001503901 | O4: =I4/1000 -> 0.00059541589 | P4: =J4/1000 -> 0.00058154949 | Q4: =SUM(L4:P4) -> 0.0041965664
A5: 2020 | B5: 2020 | C5: Indonesia | D5: Cereals | E5: Oats | F5: ='FSC data (IDN)'!O5*('Loss factors'!$E$68/100) -> 0 | G5: ='FSC data (IDN)'!P5*('Loss factors'!$F$68/100) -> 1.1203 | H5: ='FSC data (IDN)'!Q5*('Loss factors'!$G$68/100) -> 1.111579 | I5: ='FSC data (IDN)'!R5*('Loss factors'!$H$68/100) -> 0.44009001 | J5: ='FSC data (IDN)'!S5*('Loss factors'!$I$68/100) -> 0.42984093 | K5: =SUM(F5:J5) -> 3.1018099 | L5: =F5/1000 -> 0 | M5: =G5/1000 -> 0.0011203 | N5: =H5/1000 -> 0.001111579 | O5: =I5/1000 -> 0.00044009001 | P5: =J5/1000 -> 0.00042984093 | Q5: =SUM(L5:P5) -> 0.0031018099
A6: 2020 | B6: 2020 | C6: Indonesia | D6: Cereals | E6: Other cereals | F6: ='FSC data (IDN)'!O6*('Loss factors'!$E$68/100) -> 0.02 | G6: ='FSC data (IDN)'!P6*('Loss factors'!$F$68/100) -> 0.064582 | H6: ='FSC data (IDN)'!Q6*('Loss factors'!$G$68/100) -> 0.06407926 | I6: ='FSC data (IDN)'!R6*('Loss factors'!$H$68/100) -> 0.025369894 | J6: ='FSC data (IDN)'!S6*('Loss factors'!$I$68/100) -> 0.024779065 | K6: =SUM(F6:J6) -> 0.19881022 | L6: =F6/1000 -> 2e-05 | M6: =G6/1000 -> 6.4582e-05 | N6: =H6/1000 -> 6.407926e-05 | O6: =I6/1000 -> 2.5369894e-05 | P6: =J6/1000 -> 2.4779065e-05 | Q6: =SUM(L6:P6) -> 0.00019881022
